try{
   console.log(1);
   throw new Error("une erreur s'est produite pendant l'op√©ration x üòü");
   console.log(2);
}catch(error){
    console.log("une exception s'est produite : " + error);
    console.log(error.stack);
}
console.log(3);

//on peut m√™me en faire une fonction !
function reserverTable(nombrePersonne){
    if(nombrePersonne <= 0){
        throw new Error("‚õî le nombre de personne doit √™tre positif!");
    }
    if(nombrePersonne > 8){
        throw new Error("üí£ d√©sol√©, nous n'acceptons pas les groupe de plus de 8");
    }
    return "table r√©serv√©e";
}

try{
    reserverTable(10);
}catch(error){
    console.log(error.message);
}
console.log("bonjour ! ");

// On peut cr√©er une classe d'exception custom
class ErreurDeReservation extends Error{
    constructor(message){
        super(message);
        this.name = "ErreurDeReservation";
    }
}

function reserverTableCustom(nombrePersonne){
    if(nombrePersonne <= 0){
        throw new ErreurDeReservation("Le nombre de personne doit √™tre positif");
    }
    if(nombrePersonne > 8){
        throw new ErreurDeReservation("D√©sol√© on accepte pas les groupe trop grands !")
    }
    return "Table r√©serv√©e";
}
    try{
        const result = reserverTableCustom(blala);
        console.log(result);
    }catch(error){
        if(error instanceof ErreurDeReservation){
            console.log("Une erreur de r√©servation est survenue ! : " +error.message);
        }else{
            console.log("une erreur est survenue " +error);
        }
    }
    console.log("Bienvenue au resto !! ");